Workbook

Sheet Tracking
A1: DAILY MARKET TRACKING — CRUDE OIL
A2: Prices: Yahoo Finance (CL=F, BZ=F). Inventory & refinery utilization: EIA Weekly Petroleum Status Report (week-ending Friday values, released the following week).
A3: LEGEND: Blue = data inputs already filled from real sources. Yellow cells (Event / Notes) = you fill in daily. Spread is a formula — do not overwrite.
A5: Date | B5: WTI ($/bbl) | C5: Brent ($/bbl) | D5: WTI-Brent Spread ($) | E5: US Crude Inventory (M bbl) | F5: Refinery Util (%) | G5: Event | H5: Notes
A6: 46129 | B6: 83.85 | C6: 90.38 | D6: =IF(C6="","",C6-B6) -> 6.53 | E6: 465.7 | F6: 89.1 | G6: Example: OPEC meeting | H6: Example: prices firmed ahead of decision — replace with your own note
A7: 46132 | B7: 89.61 | C7: 95.48 | D7: =IF(C7="","",C7-B7) -> 5.87
A8: 46133 | B8: 92.13 | C8: 98.48 | D8: =IF(C8="","",C8-B8) -> 6.35
A9: 46134 | B9: 92.96 | C9: 101.91 | D9: =IF(C9="","",C9-B9) -> 8.95
A10: 46135 | B10: 95.85 | C10: 105.07 | D10: =IF(C10="","",C10-B10) -> 9.22
A11: 46136 | B11: 94.4 | C11: 105.33 | D11: =IF(C11="","",C11-B11) -> 10.93 | E11: 459.5 | F11: 89.6
A12: 46139 | B12: 96.37 | C12: 108.23 | D12: =IF(C12="","",C12-B12) -> 11.86
A13: 46140 | B13: 99.93 | C13: 111.26 | D13: =IF(C13="","",C13-B13) -> 11.33
A14: 46141 | B14: 106.88 | C14: 118.03 | D14: =IF(C14="","",C14-B14) -> 11.15
A15: 46142 | B15: 105.07 | C15: 114.01 | D15: =IF(C15="","",C15-B15) -> 8.94
A16: 46143 | B16: 101.94 | C16: 108.17 | D16: =IF(C16="","",C16-B16) -> 6.23 | E16: 457.2 | F16: 90.1
A17: 46146 | B17: 106.42 | C17: 114.44 | D17: =IF(C17="","",C17-B17) -> 8.02
A18: 46147 | B18: 102.27 | C18: 109.87 | D18: =IF(C18="","",C18-B18) -> 7.6
A19: 46148 | B19: 95.08 | C19: 101.27 | D19: =IF(C19="","",C19-B19) -> 6.19
A20: 46149 | B20: 94.81 | C20: 100.06 | D20: =IF(C20="","",C20-B20) -> 5.25
A21: 46150 | B21: 95.42 | C21: 101.29 | D21: =IF(C21="","",C21-B21) -> 5.87 | E21: 452.9 | F21: 91.7
A22: 46153 | B22: 98.07 | C22: 104.21 | D22: =IF(C22="","",C22-B22) -> 6.14
A23: 46154 | B23: 102.18 | C23: 107.77 | D23: =IF(C23="","",C23-B23) -> 5.59
A24: 46155 | B24: 101.02 | C24: 105.63 | D24: =IF(C24="","",C24-B24) -> 4.61
A25: 46156 | B25: 101.17 | C25: 105.72 | D25: =IF(C25="","",C25-B25) -> 4.55
A26: 46157 | B26: 105.42 | C26: 109.26 | D26: =IF(C26="","",C26-B26) -> 3.84 | E26: 445 | F26: 91.6
A27: 46160 | B27: 108.66 | C27: 112.1 | D27: =IF(C27="","",C27-B27) -> 3.44
A28: 46161 | B28: 107.77 | C28: 111.28 | D28: =IF(C28="","",C28-B28) -> 3.51
A29: 46162 | B29: 98.26 | C29: 105.02 | D29: =IF(C29="","",C29-B29) -> 6.76
A30: 46163 | B30: 96.35 | C30: 102.58 | D30: =IF(C30="","",C30-B30) -> 6.23
A31: 46164 | B31: 96.6 | C31: 103.54 | D31: =IF(C31="","",C31-B31) -> 6.94 | E31: 441.7 | F31: 94.5
A32: 46168 | B32: 93.89 | C32: 99.58 | D32: =IF(C32="","",C32-B32) -> 5.69
A33: 46169 | B33: 88.68 | C33: 94.29 | D33: =IF(C33="","",C33-B33) -> 5.61
A34: 46170 | B34: 88.9 | C34: 93.71 | D34: =IF(C34="","",C34-B34) -> 4.81
A35: 46171 | B35: 87.36 | C35: 92.05 | D35: =IF(C35="","",C35-B35) -> 4.69 | E35: 433.7 | F35: 94.7
A36: 46174 | B36: 92.16 | C36: 94.98 | D36: =IF(C36="","",C36-B36) -> 2.82
A37: 46175 | B37: 93.76 | C37: 96 | D37: =IF(C37="","",C37-B37) -> 2.24
A38: 46176 | B38: 96.02 | C38: 97.81 | D38: =IF(C38="","",C38-B38) -> 1.79
A39: 46177 | B39: 93.04 | C39: 95.03 | D39: =IF(C39="","",C39-B39) -> 1.99
A40: 46178 | B40: 90.54 | C40: 93.09 | D40: =IF(C40="","",C40-B40) -> 2.55 | E40: 426.5 | F40: 95.3
A41: 46181 | B41: 91.3 | C41: 94.25 | D41: =IF(C41="","",C41-B41) -> 2.95
...

Sheet Data
A1: Date | B1: WTI_Close | C1: Brent_Close | D1: WTI_20MA | E1: Deviation_%
A2: 42006 | B2: 52.69 | C2: 56.42
A3: 42009 | B3: 50.04 | C3: 53.11
A4: 42010 | B4: 47.93 | C4: 51.1
A5: 42011 | B5: 48.65 | C5: 51.15
A6: 42012 | B6: 48.79 | C6: 50.96
A7: 42013 | B7: 48.36 | C7: 50.11
A8: 42016 | B8: 46.07 | C8: 47.43
A9: 42017 | B9: 45.89 | C9: 46.59
A10: 42018 | B10: 48.48 | C10: 48.69
A11: 42019 | B11: 46.25 | C11: 47.67
A12: 42020 | B12: 48.69 | C12: 47.69
A13: 42024 | B13: 46.39 | C13: 47.99
... A20: 42033 | B20: 44.53 | C20: 49.13
A21: 42034 | B21: 48.24 | C21: 52.99 | D21: =AVERAGE(B2:B21) -> 47.3255 | E21: =(B21-D21)/D21*100 -> 1.932362
A22: 42037 | B22: 49.57 | C22: 54.75 | D22: =AVERAGE(B3:B22) -> 47.1695 | E22: =(B22-D22)/D22*100 -> 5.0890936
A23: 42038 | B23: 53.05 | C23: 57.91 | D23: =AVERAGE(B4:B23) -> 47.32 | E23: =(B23-D23)/D23*100 -> 12.109045
A24: 42039 | B24: 48.45 | C24: 54.16 | D24: =AVERAGE(B5:B24) -> 47.346 | E24: =(B24-D24)/D24*100 -> 2.3317704
A25: 42040 | B25: 50.48 | C25: 56.57 | D25: =AVERAGE(B6:B25) -> 47.4375 | E25: =(B25-D25)/D25*100 -> 6.4137022
A26: 42041 | B26: 51.69 | C26: 57.8 | D26: =AVERAGE(B7:B26) -> 47.5825 | E26: =(B26-D26)/D26*100 -> 8.6323753
A27: 42044 | B27: 52.86 | C27: 58.34 | D27: =AVERAGE(B8:B27) -> 47.8075 | E27: =(B27-D27)/D27*100 -> 10.568425
A28: 42045 | B28: 50.02 | C28: 56.43 | D28: =AVERAGE(B9:B28) -> 48.005 | E28: =(B28-D28)/D28*100 -> 4.1974794
A29: 42046 | B29: 48.84 | C29: 54.66 | D29: =AVERAGE(B10:B29) -> 48.1525 | E29: =(B29-D29)/D29*100 -> 1.4277556
A30: 42047 | B30: 51.21 | C30: 57.05 | D30: =AVERAGE(B11:B30) -> 48.289 | E30: =(B30-D30)/D30*100 -> 6.0489967
A31: 42048 | B31: 52.78 | C31: 57.39 | D31: =AVERAGE(B12:B31) -> 48.6155 | E31: =(B31-D31)/D31*100 -> 8.566198
A32: 42052 | B32: 53.53 | C32: 62.53 | D32: =AVERAGE(B13:B32) -> 48.8575 | E32: =(B32-D32)/D32*100 -> 9.5635266
... A2897: 46213 | B2897: 71.41 | C2897: 76.01 | D2897: =AVERAGE(B2878:B2897) -> 73.791 | E2897: =(B2897-D2897)/D2897*100 -> -3.2266808

Sheet Strategy
A1: Date | B1: Price | C1: Signal | D1: Entry_Price | E1: Exit_Price | F1: Trade_P&L_% | G1: Position | H1: Cumulative_P&L_% | I1: Running_Peak | J1: Drawdown
A2: =Data!A2 -> 42006 | B2: =Data!B2 -> 52.69 | C2: =IF(Data!D2="","HOLD",IF(AND(G1<>"IN",Data!E2<-5),"BUY",IF(AND(G1="IN",Data!E2>0),"SELL","HOLD"))) -> HOLD | D2: =IF(C2="BUY",B2,IF(G1="IN",D1,"")) | E2: =IF(C2="SELL",B2,"") | F2: =IF(E2="","",(E2-D2)/D2*100) | G2: =IF(C2="BUY","IN",IF(C2="SELL","OUT",IF(G1="IN","IN","OUT"))) -> OUT | H2: =IF(F2="",0,F2) -> 0 | I2: =H2 -> 0 | J2: =I2-H2 -> 0
A3: =Data!A3 -> 42009 | B3: =Data!B3 -> 50.04 | C3: =IF(Data!D3="","HOLD",IF(AND(G2<>"IN",Data!E3<-5),"BUY",IF(AND(G2="IN",Data!E3>0),"SELL","HOLD"))) -> HOLD | D3: =IF(C3="BUY",B3,IF(G2="IN",D2,"")) | E3: =IF(C3="SELL",B3,"") | F3: =IF(E3="","",(E3-D3)/D3*100) | G3: =IF(C3="BUY","IN",IF(C3="SELL","OUT",IF(G2="IN","IN","OUT"))) -> OUT | H3: =H2+IF(F3="",0,F3) -> 0 | I3: =MAX(I2,H3) -> 0 | J3: =I3-H3 -> 0
A4: =Data!A4 -> 42010 | B4: =Data!B4 -> 47.93 | C4: =IF(Data!D4="","HOLD",IF(AND(G3<>"IN",Data!E4<-5),"BUY",IF(AND(G3="IN",Data!E4>0),"SELL","HOLD"))) -> HOLD | D4: =IF(C4="BUY",B4,IF(G3="IN",D3,"")) | E4: =IF(C4="SELL",B4,"") | F4: =IF(E4="","",(E4-D4)/D4*100) | G4: =IF(C4="BUY","IN",IF(C4="SELL","OUT",IF(G3="IN","IN","OUT"))) -> OUT | H4: =H3+IF(F4="",0,F4) -> 0 | I4: =MAX(I3,H4) -> 0 | J4: =I4-H4 -> 0
A5: =Data!A5 -> 42011 | B5: =Data!B5 -> 48.65 | C5: =IF(Data!D5="","HOLD",IF(AND(G4<>"IN",Data!E5<-5),"BUY",IF(AND(G4="IN",Data!E5>0),"SELL","HOLD"))) -> HOLD | D5: =IF(C5="BUY",B5,IF(G4="IN",D4,"")) | E5: =IF(C5="SELL",B5,"") | F5: =IF(E5="","",(E5-D5)/D5*100) | G5: =IF(C5="BUY","IN",IF(C5="SELL","OUT",IF(G4="IN","IN","OUT"))) -> OUT | H5: =H4+IF(F5="",0,F5) -> 0 | I5: =MAX(I4,H5) -> 0 | J5: =I5-H5 -> 0
A6: =Data!A6 -> 42012 | B6: =Data!B6 -> 48.79 | C6: =IF(Data!D6="","HOLD",IF(AND(G5<>"IN",Data!E6<-5),"BUY",IF(AND(G5="IN",Data!E6>0),"SELL","HOLD"))) -> HOLD | D6: =IF(C6="BUY",B6,IF(G5="IN",D5,"")) | E6: =IF(C6="SELL",B6,"") | F6: =IF(E6="","",(E6-D6)/D6*100) | G6: =IF(C6="BUY","IN",IF(C6="SELL","OUT",IF(G5="IN","IN","OUT"))) -> OUT | H6: =H5+IF(F6="",0,F6) -> 0 | I6: =MAX(I5,H6) -> 0 | J6: =I6-H6 -> 0
A7: =Data!A7 -> 42013 | B7: =Data!B7 -> 48.36 | C7: =IF(Data!D7="","HOLD",IF(AND(G6<>"IN",Data!E7<-5),"BUY",IF(AND(G6="IN",Data!E7>0),"SELL","HOLD"))) -> HOLD | D7: =IF(C7="BUY",B7,IF(G6="IN",D6,"")) | E7: =IF(C7="SELL",B7,"") | F7: =IF(E7="","",(E7-D7)/D7*100) | G7: =IF(C7="BUY","IN",IF(C7="SELL","OUT",IF(G6="IN","IN","OUT"))) -> OUT | H7: =H6+IF(F7="",0,F7) -> 0 | I7: =MAX(I6,H7) -> 0 | J7: =I7-H7 -> 0
A8: =Data!A8 -> 42016 | B8: =Data!B8 -> 46.07 | C8: =IF(Data!D8="","HOLD",IF(AND(G7<>"IN",Data!E8<-5),"BUY",IF(AND(G7="IN",Data!E8>0),"SELL","HOLD"))) -> HOLD | D8: =IF(C8="BUY",B8,IF(G7="IN",D7,"")) | E8: =IF(C8="SELL",B8,"") | F8: =IF(E8="","",(E8-D8)/D8*100) | G8: =IF(C8="BUY","IN",IF(C8="SELL","OUT",IF(G7="IN","IN","OUT"))) -> OUT | H8: =H7+IF(F8="",0,F8) -> 0 | I8: =MAX(I7,H8) -> 0 | J8: =I8-H8 -> 0
A9: =Data!A9 -> 42017 | B9: =Data!B9 -> 45.89 | C9: =IF(Data!D9="","HOLD",IF(AND(G8<>"IN",Data!E9<-5),"BUY",IF(AND(G8="IN",Data!E9>0),"SELL","HOLD"))) -> HOLD | D9: =IF(C9="BUY",B9,IF(G8="IN",D8,"")) | E9: =IF(C9="SELL",B9,"") | F9: =IF(E9="","",(E9-D9)/D9*100) | G9: =IF(C9="BUY","IN",IF(C9="SELL","OUT",IF(G8="IN","IN","OUT"))) -> OUT | H9: =H8+IF(F9="",0,F9) -> 0 | I9: =MAX(I8,H9) -> 0 | J9: =I9-H9 -> 0
A10: =Data!A10 -> 42018 | B10: =Data!B10 -> 48.48 | C10: =IF(Data!D10="","HOLD",IF(AND(G9<>"IN",Data!E10<-5),"BUY",IF(AND(G9="IN",Data!E10>0),"SELL","HOLD"))) -> HOLD | D10: =IF(C10="BUY",B10,IF(G9="IN",D9,"")) | E10: =IF(C10="SELL",B10,"") | F10: =IF(E10="","",(E10-D10)/D10*100) | G10: =IF(C10="BUY","IN",IF(C10="SELL","OUT",IF(G9="IN","IN","OUT"))) -> OUT | H10: =H9+IF(F10="",0,F10) -> 0 | I10: =MAX(I9,H10) -> 0 | J10: =I10-H10 -> 0
A11: =Data!A11 -> 42019 | B11: =Data!B11 -> 46.25 | C11: =IF(Data!D11="","HOLD",IF(AND(G10<>"IN",Data!E11<-5),"BUY",IF(AND(G10="IN",Data!E11>0),"SELL","HOLD"))) -> HOLD | D11: =IF(C11="BUY",B11,IF(G10="IN",D10,"")) | E11: =IF(C11="SELL",B11,"") | F11: =IF(E11="","",(E11-D11)/D11*100) | G11: =IF(C11="BUY","IN",IF(C11="SELL","OUT",IF(G10="IN","IN","OUT"))) -> OUT | H11: =H10+IF(F11="",0,F11) -> 0 | I11: =MAX(I10,H11) -> 0 | J11: =I11-H11 -> 0
A12: =Data!A12 -> 42020 | B12: =Data!B12 -> 48.69 | C12: =IF(Data!D12="","HOLD",IF(AND(G11<>"IN",Data!E12<-5),"BUY",IF(AND(G11="IN",Data!E12>0),"SELL","HOLD"))) -> HOLD | D12: =IF(C12="BUY",B12,IF(G11="IN",D11,"")) | E12: =IF(C12="SELL",B12,"") | F12: =IF(E12="","",(E12-D12)/D12*100) | G12: =IF(C12="BUY","IN",IF(C12="SELL","OUT",IF(G11="IN","IN","OUT"))) -> OUT | H12: =H11+IF(F12="",0,F12) -> 0 | I12: =MAX(I11,H12) -> 0 | J12: =I12-H12 -> 0
A13: =Data!A13 -> 42024 | B13: =Data!B13 -> 46.39 | C13: =IF(Data!D13="","HOLD",IF(AND(G12<>"IN",Data!E13<-5),"BUY",IF(AND(G12="IN",Data!E13>0),"SELL","HOLD"))) -> HOLD | D13: =IF(C13="BUY",B13,IF(G12="IN",D12,"")) | E13: =IF(C13="SELL",B13,"") | F13: =IF(E13="","",(E13-D13)/D13*100) | G13: =IF(C13="BUY","IN",IF(C13="SELL","OUT",IF(G12="IN","IN","OUT"))) -> OUT | H13: =H12+IF(F13="",0,F13) -> 0 | I13: =MAX(I12,H13) -> 0 | J13: =I13-H13 -> 0
A14: =Data!A14 -> 42025 | B14: =Data!B14 -> 47.78 | C14: =IF(Data!D14="","HOLD",IF(AND(G13<>"IN",Data!E14<-5),"BUY",IF(AND(G13="IN",Data!E14>0),"SELL","HOLD"))) -> HOLD | D14: =IF(C14="BUY",B14,IF(G13="IN",D13,"")) | E14: =IF(C14="SELL",B14,"") | F14: =IF(E14="","",(E14-D14)/D14*100) | G14: =IF(C14="BUY","IN",IF(C14="SELL","OUT",IF(G13="IN","IN","OUT"))) -> OUT | H14: =H13+IF(F14="",0,F14) -> 0 | I14: =MAX(I13,H14) -> 0 | J14: =I14-H14 -> 0
... A2897: =Data!A2897 -> 46213 | B2897: =Data!B2897 -> 71.41 | C2897: =IF(Data!D2897="","HOLD",IF(AND(G2896<>"IN",Data!E2897<-5),"BUY",IF(AND(G2896="IN",Data!E2897>0),"SELL","HOLD"))) -> HOLD | D2897: =IF(C2897="BUY",B2897,IF(G2896="IN",D2896,"")) -> 93.89 | E2897: =IF(C2897="SELL",B2897,"") | F2897: =IF(E2897="","",(E2897-D2897)/D2897*100) | G2897: =IF(C2897="BUY","IN",IF(C2897="SELL","OUT",IF(G2896="IN","IN","OUT"))) -> IN | H2897: =H2896+IF(F2897="",0,F2897) -> 74.456229 | I2897: =MAX(I2896,H2897) -> 74.456229 | J2897: =I2897-H2897 -> 0

Sheet Results
A1: CRUDE OIL MEAN REVERSION — BACKTEST RESULTS
A2: Strategy: BUY WTI when price closes 5% below its 20-day moving average; SELL when price recovers above the average.
A3: Data: WTI front-month futures (CL=F), 2015-01-02 to 2026-07-10, 2896 trading days. Source: Yahoo Finance.
A5: PERFORMANCE METRICS
A6: Total Trades | B6: =COUNT(Strategy!F2:F2897) -> 59
A7: Winning Trades | B7: =COUNTIF(Strategy!F2:F2897,">0") -> 42
A8: Losing Trades | B8: =COUNTIF(Strategy!F2:F2897,"<0") -> 17
A9: Win Rate (%) | B9: =IF(B6=0,0,B7/B6*100) -> 71.186441
A10: Average Win (%) | B10: =IFERROR(AVERAGEIF(Strategy!F2:F2897,">0"),0) -> 5.3179564
A11: Average Loss (%) | B11: =IFERROR(AVERAGEIF(Strategy!F2:F2897,"<0"),0) -> -8.7587023
A12: Profit Factor | B12: =IFERROR(SUMIF(Strategy!F2:F2897,">0")/ABS(SUMIF(Strategy!F2:F2897,"<0")),0) -> 1.5000488
A13: Total Strategy P&L (sum of trade %, unleveraged) | B13: =SUM(Strategy!F2:F2897) -> 74.456229
A14: Max Drawdown of cumulative P&L (pct-pts) | B14: =MAX(Strategy!J2:J2897) -> 82.4356
A16: BENCHMARK COMPARISON
A17: Buy & Hold Return (%) | B17: =(Data!B2897-Data!B2)/Data!B2*100 -> 35.528563
A18: Strategy Total P&L (%) | B18: =B13 -> 74.456229
A19: Outperformance (pct-pts) | B19: =B18-B17 -> 38.927666
A22: HONEST LIMITATIONS (mention these in interviews — they add credibility):
A23: • Transaction costs and slippage are NOT modeled (real cost roughly $0.05–0.10/bbl per side).
A24: • Uses front-month continuous futures — roll costs in contango are not captured.
A25: • No stop-loss: the strategy rides losses until recovery, so single trades can lose heavily (see 2020).
A26: • Trade P&L is per-trade % with full notional each time; no compounding or position sizing applied.
A27: IMPROVEMENT IDEAS: add a -4% stop-loss, test -3%/-7% thresholds, test on Brent (column C in Data), add volatility filter.
